<sdf version='1.7'>
  <model name='car_suspension'>
    <link name='car_body'>
      <inertial>
        <pose>0 0 0 0 -0 0</pose>
        <mass>100</mass>
        <inertia>
          <ixx>10</ixx>
          <ixy>0</ixy>
          <ixz>0</ixz>
          <iyy>10</iyy>
          <iyz>0</iyz>
          <izz>10</izz>
        </inertia>
      </inertial>
      <collision name='car_body_collision'>
        <pose>0 0 0 0 -0 0</pose>
        <geometry>
          <box>
            <size>0.4 0.8 0.2</size>
          </box>
        </geometry>
      </collision>
      <visual name='car_body_visual'>
        <pose>0 0 0 0 -0 0</pose>
        <geometry>
          <box>
            <size>0.4 0.8 0.4</size>
          </box>
        </geometry>
      </visual>
    </link>
    <joint name='suspension_back' type='prismatic'>
      <pose relative_to='car_body'>0 -0.35 0 0 -0 0</pose>
      <parent>car_body</parent>
      <child>back_wheel_body</child>
      <axis>
        <xyz>0 0 1</xyz>
        <limit>
          <lower>-0.05</lower>
          <upper>0.05</upper>
          <effort>10000</effort>
          <velocity>2</velocity>
        </limit>
        <dynamics>
          <damping>0.8</damping>
          <friction>0</friction>
          <spring_reference>0</spring_reference>
          <spring_stiffness>2</spring_stiffness>
        </dynamics>
      </axis>
    </joint>
    <link name='back_wheel_body'>
      <pose relative_to='suspension_back'>0 0 0 0 -0 0</pose>
      <inertial>
        <pose>0 0 0 0 -0 0</pose>
        <mass>1</mass>
        <inertia>
          <ixx>0.1</ixx>
          <ixy>0</ixy>
          <ixz>0</ixz>
          <iyy>0.1</iyy>
          <iyz>0</iyz>
          <izz>0.1</izz>
        </inertia>
      </inertial>
      <collision name='back_wheel_body_collision'>
        <pose>0 0 -0.125 0 -0 0</pose>
        <geometry>
          <box>
            <size>0.6 0.1 0.05</size>
          </box>
        </geometry>
      </collision>
      <visual name='back_wheel_body_visual'>
        <pose>0 0 -0.125 0 -0 0</pose>
        <geometry>
          <box>
            <size>0.6 0.1 0.05</size>
          </box>
        </geometry>
      </visual>
    </link>
    <joint name='back_body_to_left_wheel' type='revolute'>
      <pose relative_to='back_wheel_body'>-0.3 0 -0.125 0 -0 0</pose>
      <parent>back_wheel_body</parent>
      <child>back_wheel_left</child>
      <axis>
        <xyz>1 0 0</xyz>
        <limit>
          <effort>10000</effort>
          <velocity>2</velocity>
          <lower>-1e+16</lower>
          <upper>1e+16</upper>
        </limit>
        <dynamics>
          <spring_reference>0</spring_reference>
          <spring_stiffness>0</spring_stiffness>
        </dynamics>
      </axis>
    </joint>
    <link name='back_wheel_left'>
      <pose relative_to='back_body_to_left_wheel'>0 0 0 0 -0 0</pose>
      <inertial>
        <pose>0 0 0 0 -0 0</pose>
        <mass>1</mass>
        <inertia>
          <ixx>0.1</ixx>
          <ixy>0</ixy>
          <ixz>0</ixz>
          <iyy>0.1</iyy>
          <iyz>0</iyz>
          <izz>0.1</izz>
        </inertia>
      </inertial>
      <collision name='back_wheel_left_collision'>
        <pose>-0.05 0 0 0 -1.5708 0</pose>
        <geometry>
          <cylinder>
            <length>0.1</length>
            <radius>0.2</radius>
          </cylinder>
        </geometry>
        <surface>
          <friction>
            <ode>
              <mu>0.7</mu>
              <mu2>0.7</mu2>
              <fdir1>1 0 0</fdir1>
            </ode>
          </friction>
          <contact>
            <ode>
              <kp>1e+13</kp>
              <kd>1</kd>
              <max_vel>10</max_vel>
            </ode>
          </contact>
          <bounce>
            <restitution_coefficient>0</restitution_coefficient>
            <threshold>0</threshold>
          </bounce>
        </surface>
      </collision>
      <visual name='back_wheel_left_visual'>
        <pose>-0.05 0 0 0 -1.5708 0</pose>
        <geometry>
          <cylinder>
            <length>0.1</length>
            <radius>0.2</radius>
          </cylinder>
        </geometry>
      </visual>
    </link>
    <joint name='back_body_to_right_wheel' type='revolute'>
      <pose relative_to='back_wheel_body'>0.3 0 -0.125 0 -0 0</pose>
      <parent>back_wheel_body</parent>
      <child>back_wheel_right</child>
      <axis>
        <xyz>1 0 0</xyz>
        <limit>
          <effort>10000</effort>
          <velocity>2</velocity>
          <lower>-1e+16</lower>
          <upper>1e+16</upper>
        </limit>
        <dynamics>
          <spring_reference>0</spring_reference>
          <spring_stiffness>0</spring_stiffness>
        </dynamics>
      </axis>
    </joint>
    <link name='back_wheel_right'>
      <pose relative_to='back_body_to_right_wheel'>0 0 0 0 -0 0</pose>
      <inertial>
        <pose>0 0 0 0 -0 0</pose>
        <mass>1</mass>
        <inertia>
          <ixx>0.1</ixx>
          <ixy>0</ixy>
          <ixz>0</ixz>
          <iyy>0.1</iyy>
          <iyz>0</iyz>
          <izz>0.1</izz>
        </inertia>
      </inertial>
      <collision name='back_wheel_right_collision'>
        <pose>0.05 0 0 0 -1.5708 0</pose>
        <geometry>
          <cylinder>
            <length>0.1</length>
            <radius>0.2</radius>
          </cylinder>
        </geometry>
        <surface>
          <friction>
            <ode>
              <mu>0.7</mu>
              <mu2>0.7</mu2>
              <fdir1>1 0 0</fdir1>
            </ode>
          </friction>
          <contact>
            <ode>
              <kp>1e+13</kp>
              <kd>1</kd>
              <max_vel>10</max_vel>
            </ode>
          </contact>
          <bounce>
            <restitution_coefficient>0</restitution_coefficient>
            <threshold>0</threshold>
          </bounce>
        </surface>
      </collision>
      <visual name='back_wheel_right_visual'>
        <pose>0.05 0 0 0 -1.5708 0</pose>
        <geometry>
          <cylinder>
            <length>0.1</length>
            <radius>0.2</radius>
          </cylinder>
        </geometry>
      </visual>
    </link>
    <joint name='suspension_front' type='prismatic'>
      <pose relative_to='car_body'>0 0.35 0 0 -0 0</pose>
      <parent>car_body</parent>
      <child>front_wheel_body</child>
      <axis>
        <xyz>0 0 1</xyz>
        <limit>
          <lower>-0.05</lower>
          <upper>0.05</upper>
          <effort>10000</effort>
          <velocity>2</velocity>
        </limit>
        <dynamics>
          <damping>0.8</damping>
          <friction>0</friction>
          <spring_reference>0</spring_reference>
          <spring_stiffness>2</spring_stiffness>
        </dynamics>
      </axis>
    </joint>
    <link name='front_wheel_body'>
      <pose relative_to='suspension_front'>0 0 0 0 -0 0</pose>
      <inertial>
        <pose>0 0 0 0 -0 0</pose>
        <mass>1</mass>
        <inertia>
          <ixx>0.1</ixx>
          <ixy>0</ixy>
          <ixz>0</ixz>
          <iyy>0.1</iyy>
          <iyz>0</iyz>
          <izz>0.1</izz>
        </inertia>
      </inertial>
      <collision name='front_wheel_body_collision'>
        <pose>0 0 -0.125 0 -0 0</pose>
        <geometry>
          <box>
            <size>0.6 0.1 0.05</size>
          </box>
        </geometry>
      </collision>
      <visual name='front_wheel_body_visual'>
        <pose>0 0 -0.125 0 -0 0</pose>
        <geometry>
          <box>
            <size>0.6 0.1 0.05</size>
          </box>
        </geometry>
      </visual>
    </link>
    <joint name='front_body_to_left_wheel' type='revolute'>
      <pose relative_to='front_wheel_body'>-0.3 0 -0.125 0 -0 0</pose>
      <parent>front_wheel_body</parent>
      <child>front_wheel_left</child>
      <axis>
        <xyz>1 0 0</xyz>
        <limit>
          <effort>10000</effort>
          <velocity>2</velocity>
          <lower>-1e+16</lower>
          <upper>1e+16</upper>
        </limit>
        <dynamics>
          <spring_reference>0</spring_reference>
          <spring_stiffness>0</spring_stiffness>
        </dynamics>
      </axis>
    </joint>
    <link name='front_wheel_left'>
      <pose relative_to='front_body_to_left_wheel'>0 0 0 0 -0 0</pose>
      <inertial>
        <pose>0 0 0 0 -0 0</pose>
        <mass>1</mass>
        <inertia>
          <ixx>0.1</ixx>
          <ixy>0</ixy>
          <ixz>0</ixz>
          <iyy>0.1</iyy>
          <iyz>0</iyz>
          <izz>0.1</izz>
        </inertia>
      </inertial>
      <collision name='front_wheel_left_collision'>
        <pose>-0.05 0 0 0 -1.5708 0</pose>
        <geometry>
          <cylinder>
            <length>0.1</length>
            <radius>0.2</radius>
          </cylinder>
        </geometry>
        <surface>
          <friction>
            <ode>
              <mu>0.7</mu>
              <mu2>0.7</mu2>
              <fdir1>1 0 0</fdir1>
            </ode>
          </friction>
          <contact>
            <ode>
              <kp>1e+13</kp>
              <kd>1</kd>
              <max_vel>10</max_vel>
            </ode>
          </contact>
          <bounce>
            <restitution_coefficient>0</restitution_coefficient>
            <threshold>0</threshold>
          </bounce>
        </surface>
      </collision>
      <visual name='front_wheel_left_visual'>
        <pose>-0.05 0 0 0 -1.5708 0</pose>
        <geometry>
          <cylinder>
            <length>0.1</length>
            <radius>0.2</radius>
          </cylinder>
        </geometry>
      </visual>
    </link>
    <joint name='front_body_to_right_wheel' type='revolute'>
      <pose relative_to='front_wheel_body'>0.3 0 -0.125 0 -0 0</pose>
      <parent>front_wheel_body</parent>
      <child>front_wheel_right</child>
      <axis>
        <xyz>1 0 0</xyz>
        <limit>
          <effort>10000</effort>
          <velocity>2</velocity>
          <lower>-1e+16</lower>
          <upper>1e+16</upper>
        </limit>
        <dynamics>
          <spring_reference>0</spring_reference>
          <spring_stiffness>0</spring_stiffness>
        </dynamics>
      </axis>
    </joint>
    <link name='front_wheel_right'>
      <pose relative_to='front_body_to_right_wheel'>0 0 0 0 -0 0</pose>
      <inertial>
        <pose>0 0 0 0 -0 0</pose>
        <mass>1</mass>
        <inertia>
          <ixx>0.1</ixx>
          <ixy>0</ixy>
          <ixz>0</ixz>
          <iyy>0.1</iyy>
          <iyz>0</iyz>
          <izz>0.1</izz>
        </inertia>
      </inertial>
      <collision name='front_wheel_right_collision'>
        <pose>0.05 0 0 0 -1.5708 0</pose>
        <geometry>
          <cylinder>
            <length>0.1</length>
            <radius>0.2</radius>
          </cylinder>
        </geometry>
        <surface>
          <friction>
            <ode>
              <mu>0.7</mu>
              <mu2>0.7</mu2>
              <fdir1>1 0 0</fdir1>
            </ode>
          </friction>
          <contact>
            <ode>
              <kp>1e+13</kp>
              <kd>1</kd>
              <max_vel>10</max_vel>
            </ode>
          </contact>
          <bounce>
            <restitution_coefficient>0</restitution_coefficient>
            <threshold>0</threshold>
          </bounce>
        </surface>
      </collision>
      <visual name='front_wheel_right_visual'>
        <pose>0.05 0 0 0 -1.5708 0</pose>
        <geometry>
          <cylinder>
            <length>0.1</length>
            <radius>0.2</radius>
          </cylinder>
        </geometry>
      </visual>
    </link>
  </model>
</sdf>
