<?xml version="1.0" ?>

<robot name="tricycle_model">
  <link name="base_dummy">
  </link>

  <joint name="base_link_joint" type="fixed">
    <origin rpy="0 0 0" xyz="0 0 0"/>
    <parent link="base_dummy"/>
    <child link="Chassis"/>
  </joint>

  <link name="Chassis">
    <inertial>
      <origin rpy="0 0 0" xyz="0 0 0"/>
      <mass value="0.388"/>
      <inertia ixx="0.001787" ixy="0" ixz="0" iyy="0.000979" iyz="0" izz="0.001172"/>
    </inertial>
    <collision>
      <geometry>
        <box size="0.075 0.175 0.157"/>
      </geometry>
      <origin rpy="0 0 0" xyz="0 0 0"/>
    </collision>
    <visual>
      <geometry>
        <box size = "0.075 0.175 0.157"/>
      </geometry>
      <origin rpy="0 0 0" xyz="0 0 0"/>
    </visual>
  </link>

  <link name="Right_wheel">
    <inertial>
      <origin rpy="0 0 0" xyz="0 0 0"/>
      <mass value="0.03770"/>
      <inertia ixx="0.000013712" ixy="0" ixz="0" iyy="0.000018823" iyz="0" izz="0.000013712"/>
    </inertial>
    <collision>
      <geometry>
        <cylinder length="0.037" radius="0.0316"/>
      </geometry>
      <origin rpy="1.5708 0 0" xyz="0 0 0"/>
    </collision>
    <visual>
      <geometry>
        <cylinder length="0.037" radius="0.0316"/>
      </geometry>
      <origin rpy="1.5708 0 0" xyz="0 0 0"/>
    </visual>
  </link>

  <joint name="Right_wheel_Joint" type="continuous">
    <parent link="Chassis"/>
    <child link="Right_wheel"/>
    <origin rpy="0 0 0" xyz="-0.010 0.1075 -0.0785"/>
    <limit effort="100000" velocity="100000"/>
    <axis xyz="0 1 0"/>
  </joint>

  <link name="Left_wheel">
    <inertial>
      <origin rpy="0 0 0" xyz="0 0 0"/>
      <mass value="0.03770"/>
      <inertia ixx="0.000013712" ixy="0" ixz="0" iyy="0.000018823" iyz="0" izz="0.000013712"/>
    </inertial>
    <collision>
      <geometry>
        <cylinder length="0.037" radius="0.0316"/>
      </geometry>
      <origin rpy="1.5708 0 0" xyz="0 0 0"/>
    </collision>
    <visual>
      <geometry>
        <cylinder length="0.037" radius="0.0316"/>
      </geometry>
      <origin rpy="1.5708 0 0" xyz="0 0 0"/>
    </visual>
  </link>

  <joint name="Left_wheel_Joint" type="continuous">
    <parent link="Chassis"/>
    <child link="Left_wheel"/>
    <origin rpy="0 0 0" xyz="-0.010 -0.1075 -0.0785"/>
    <limit effort="100000" velocity="100000"/>
    <axis xyz="0 1 0"/>
  </joint>

  <link name="Front_body">
    <inertial>
      <origin rpy="0 0 0" xyz="0 0 0"/>
      <mass value="0.151"/>
      <inertia ixx="0.000157" ixy="0" ixz="0" iyy=".000448" iyz="0" izz=".000354"/>
    </inertial>
    <collision>
      <geometry>
        <box size="0.160 0.050 0.100"/>
      </geometry>
      <origin rpy="0 0 0" xyz="0 0 0"/>
    </collision>
    <visual>
      <geometry>
        <box size = "0.160 0.050 0.100"/>
      </geometry>
      <origin rpy="0 0 0" xyz="0 0 0"/>
    </visual>
  </link>

  <joint name="Front_body_Joint" type="fixed">
    <parent link="Chassis"/>
    <child link="Front_body"/>
    <origin rpy="0 0 0" xyz="0.1175 0.0 -0.0285"/>
  </joint>

  <link name="Front_Steered">
    <inertial>
      <origin rpy="0 0 0" xyz="0 0 0"/>
      <mass value="0.151"/>
      <inertia ixx="0.000157" ixy="0" ixz="0" iyy=".000448" iyz="0" izz=".000354"/>
    </inertial>
    <collision>
      <geometry>
        <box size="0.050 0.050 0.157"/>
      </geometry>
      <origin rpy="0 0 0" xyz="0 0 0"/>
    </collision>
    <visual>
      <geometry>
        <box size = "0.050 0.050 0.157"/>
      </geometry>
      <origin rpy="0 0 0" xyz="0 0 0"/>
    </visual>
  </link>

  <joint name="Front_Steering_Joint" type="continuous">
    <parent link="Front_body"/>
    <child link="Front_Steered"/>
    <origin rpy="0 0 0" xyz="0.105 0.0 0.0285"/>
    <limit effort="100000" velocity="100000"/>
    <axis xyz="0 0 1"/>
  </joint>

  <link name="Front_wheel">
    <inertial>
      <origin rpy="0 0 0" xyz="0 0 0"/>
      <mass value="0.03770"/>
      <inertia ixx="0.000013712" ixy="0" ixz="0" iyy="0.000018823" iyz="0" izz="0.000013712"/>
    </inertial>
    <collision>
      <geometry>
        <cylinder length="0.037" radius="0.0316"/>
      </geometry>
      <origin rpy="1.5708 0 0" xyz="0 0 0"/>
    </collision>
    <visual>
      <geometry>
        <cylinder length="0.037" radius="0.0316"/>
      </geometry>
      <origin rpy="1.5708 0 0" xyz="0 0 0"/>
    </visual>
  </link>

  <joint name="Front_wheel_Joint" type="continuous">
    <parent link="Front_Steered"/>
    <child link="Front_wheel"/>
    <origin rpy="0 0 0" xyz="0.0 0.0 -0.0785"/>
    <limit effort="100000" velocity="100000"/>
    <axis xyz="0 1 0"/>
  </joint>


  <gazebo reference="Left_wheel">
    <mu1>0.90</mu1>
    <mu2>0.90</mu2>
    <kp>100000000</kp>
    <kd>10</kd>
    <material>Gazebo/Red</material>
  </gazebo>
  <gazebo reference="Right_wheel">
    <mu1>0.90</mu1>
    <mu2>0.90</mu2>
    <kp>100000000</kp>
    <kd>10</kd>
    <material>Gazebo/Green</material>
  </gazebo>
  <gazebo reference="Front_wheel">
    <mu1>0.90</mu1>
    <mu2>0.90</mu2>
    <kp>100000000</kp>
    <kd>10</kd>
    <material>Gazebo/Blue</material>
  </gazebo>
  <gazebo reference="Front_Steered">
    <sensor name="IMU_Sensor" type="imu">
    <always_on>1</always_on>
    <update_rate>100.0</update_rate>
    <visualize>true</visualize>
    </sensor>
  </gazebo>


  <ros2_control name="GazeboSystem" type="system">
    <hardware>
      <plugin>gazebo_ros2_control/GazeboSystem</plugin>
    </hardware>
    
    <joint name="Front_wheel_Joint">
      <command_interface name="velocity">
        <param name="min">-10</param>
        <param name="max">10</param>
      </command_interface>
      <state_interface name="position"/>
      <state_interface name="velocity"/>
      <state_interface name="effort"/>
    </joint>

    <joint name="Front_Steering_Joint">
      <command_interface name="position">
        <param name="min">-10</param>
        <param name="max">10</param>
      </command_interface>
      <state_interface name="position"/>
      <state_interface name="velocity"/>
      <state_interface name="effort"/>
    </joint>

    <sensor name = "IMU_Sensor">
      <state_interface name="orientation.x"/>
      <state_interface name="orientation.y"/>
      <state_interface name="orientation.z"/>
      <state_interface name="orientation.w"/>
      <state_interface name="angular_velocity.x"/>
      <state_interface name="angular_velocity.y"/>
      <state_interface name="angular_velocity.z"/>
      <state_interface name="linear_acceleration.x"/>
      <state_interface name="linear_acceleration.y"/>
      <state_interface name="linear_acceleration.z"/>
    </sensor>
    
  </ros2_control>


 <gazebo>
    <plugin filename="libgazebo_ros2_control.so" name="gazebo_ros2_control">
      <parameters>$(find tricycle)/config/tricycle_position_velocity_controller.yaml</parameters>
    </plugin>
  </gazebo>

</robot>

